2019-09-03 11:20:27,726 ERROR: Exception on /login [GET] [in /Users/amyliz/Documents/Computer Science/Python/microblog/venv/lib/python3.7/site-packages/flask/app.py:1891]
Traceback (most recent call last):
  File "/Users/amyliz/Documents/Computer Science/Python/microblog/venv/lib/python3.7/site-packages/flask/app.py", line 2446, in wsgi_app
    response = self.full_dispatch_request()
  File "/Users/amyliz/Documents/Computer Science/Python/microblog/venv/lib/python3.7/site-packages/flask/app.py", line 1951, in full_dispatch_request
    rv = self.handle_user_exception(e)
  File "/Users/amyliz/Documents/Computer Science/Python/microblog/venv/lib/python3.7/site-packages/flask/app.py", line 1820, in handle_user_exception
    reraise(exc_type, exc_value, tb)
  File "/Users/amyliz/Documents/Computer Science/Python/microblog/venv/lib/python3.7/site-packages/flask/_compat.py", line 39, in reraise
    raise value
  File "/Users/amyliz/Documents/Computer Science/Python/microblog/venv/lib/python3.7/site-packages/flask/app.py", line 1949, in full_dispatch_request
    rv = self.dispatch_request()
  File "/Users/amyliz/Documents/Computer Science/Python/microblog/venv/lib/python3.7/site-packages/flask/app.py", line 1935, in dispatch_request
    return self.view_functions[rule.endpoint](**req.view_args)
  File "/Users/amyliz/Documents/Computer Science/Python/microblog/app/routes.py", line 46, in login
    return render_template('login.html', title='Sign In', form=form)
  File "/Users/amyliz/Documents/Computer Science/Python/microblog/venv/lib/python3.7/site-packages/flask/templating.py", line 140, in render_template
    ctx.app,
  File "/Users/amyliz/Documents/Computer Science/Python/microblog/venv/lib/python3.7/site-packages/flask/templating.py", line 120, in _render
    rv = template.render(context)
  File "/Users/amyliz/Documents/Computer Science/Python/microblog/venv/lib/python3.7/site-packages/jinja2/asyncsupport.py", line 76, in render
    return original_render(self, *args, **kwargs)
  File "/Users/amyliz/Documents/Computer Science/Python/microblog/venv/lib/python3.7/site-packages/jinja2/environment.py", line 1008, in render
    return self.environment.handle_exception(exc_info, True)
  File "/Users/amyliz/Documents/Computer Science/Python/microblog/venv/lib/python3.7/site-packages/jinja2/environment.py", line 780, in handle_exception
    reraise(exc_type, exc_value, tb)
  File "/Users/amyliz/Documents/Computer Science/Python/microblog/venv/lib/python3.7/site-packages/jinja2/_compat.py", line 37, in reraise
    raise value.with_traceback(tb)
  File "/Users/amyliz/Documents/Computer Science/Python/microblog/app/templates/base.html", line 82, in template
    {% block content %}{% endblock %}
  File "/Users/amyliz/Documents/Computer Science/Python/microblog/venv/lib/python3.7/site-packages/jinja2/environment.py", line 1005, in render
    return concat(self.root_render_func(self.new_context(vars)))
  File "/Users/amyliz/Documents/Computer Science/Python/microblog/app/templates/login.html", line 1, in top-level template code
    {% extends "base.html" %}
  File "/Users/amyliz/Documents/Computer Science/Python/microblog/venv/lib/python3.7/site-packages/jinja2/environment.py", line 780, in handle_exception
    reraise(exc_type, exc_value, tb)
  File "/Users/amyliz/Documents/Computer Science/Python/microblog/venv/lib/python3.7/site-packages/jinja2/_compat.py", line 37, in reraise
    raise value.with_traceback(tb)
  File "/Users/amyliz/Documents/Computer Science/Python/microblog/app/templates/base.html", line 82, in template
    {% block content %}{% endblock %}
  File "/Users/amyliz/Documents/Computer Science/Python/microblog/venv/lib/python3.7/site-packages/jinja2/environment.py", line 543, in _generate
    optimized=self.optimized)
  File "/Users/amyliz/Documents/Computer Science/Python/microblog/venv/lib/python3.7/site-packages/jinja2/compiler.py", line 82, in generate
    generator.visit(node)
  File "/Users/amyliz/Documents/Computer Science/Python/microblog/venv/lib/python3.7/site-packages/jinja2/visitor.py", line 38, in visit
    return f(node, *args, **kwargs)
  File "/Users/amyliz/Documents/Computer Science/Python/microblog/venv/lib/python3.7/site-packages/jinja2/compiler.py", line 718, in visit_Template
    self.fail('block %r defined twice' % block.name, block.lineno)
  File "/Users/amyliz/Documents/Computer Science/Python/microblog/venv/lib/python3.7/site-packages/jinja2/compiler.py", line 315, in fail
    raise TemplateAssertionError(msg, lineno, self.name, self.filename)
jinja2.exceptions.TemplateAssertionError: block 'content' defined twice
2019-09-03 11:20:28,774 ERROR: Exception on /favicon.ico [GET] [in /Users/amyliz/Documents/Computer Science/Python/microblog/venv/lib/python3.7/site-packages/flask/app.py:1891]
Traceback (most recent call last):
  File "/Users/amyliz/Documents/Computer Science/Python/microblog/venv/lib/python3.7/site-packages/flask/app.py", line 1949, in full_dispatch_request
    rv = self.dispatch_request()
  File "/Users/amyliz/Documents/Computer Science/Python/microblog/venv/lib/python3.7/site-packages/flask/app.py", line 1925, in dispatch_request
    self.raise_routing_exception(req)
  File "/Users/amyliz/Documents/Computer Science/Python/microblog/venv/lib/python3.7/site-packages/flask/app.py", line 1907, in raise_routing_exception
    raise request.routing_exception
  File "/Users/amyliz/Documents/Computer Science/Python/microblog/venv/lib/python3.7/site-packages/flask/ctx.py", line 350, in match_request
    result = self.url_adapter.match(return_rule=True)
  File "/Users/amyliz/Documents/Computer Science/Python/microblog/venv/lib/python3.7/site-packages/werkzeug/routing.py", line 1799, in match
    raise NotFound()
werkzeug.exceptions.NotFound: 404 Not Found: The requested URL was not found on the server. If you entered the URL manually please check your spelling and try again.

During handling of the above exception, another exception occurred:

Traceback (most recent call last):
  File "/Users/amyliz/Documents/Computer Science/Python/microblog/venv/lib/python3.7/site-packages/flask/app.py", line 2446, in wsgi_app
    response = self.full_dispatch_request()
  File "/Users/amyliz/Documents/Computer Science/Python/microblog/venv/lib/python3.7/site-packages/flask/app.py", line 1951, in full_dispatch_request
    rv = self.handle_user_exception(e)
  File "/Users/amyliz/Documents/Computer Science/Python/microblog/venv/lib/python3.7/site-packages/flask/app.py", line 1815, in handle_user_exception
    return self.handle_http_exception(e)
  File "/Users/amyliz/Documents/Computer Science/Python/microblog/venv/lib/python3.7/site-packages/flask/app.py", line 1743, in handle_http_exception
    return handler(e)
  File "/Users/amyliz/Documents/Computer Science/Python/microblog/app/errors.py", line 6, in not_found_error
    return render_template('404.html'), 404
  File "/Users/amyliz/Documents/Computer Science/Python/microblog/venv/lib/python3.7/site-packages/flask/templating.py", line 140, in render_template
    ctx.app,
  File "/Users/amyliz/Documents/Computer Science/Python/microblog/venv/lib/python3.7/site-packages/flask/templating.py", line 120, in _render
    rv = template.render(context)
  File "/Users/amyliz/Documents/Computer Science/Python/microblog/venv/lib/python3.7/site-packages/jinja2/asyncsupport.py", line 76, in render
    return original_render(self, *args, **kwargs)
  File "/Users/amyliz/Documents/Computer Science/Python/microblog/venv/lib/python3.7/site-packages/jinja2/environment.py", line 1008, in render
    return self.environment.handle_exception(exc_info, True)
  File "/Users/amyliz/Documents/Computer Science/Python/microblog/venv/lib/python3.7/site-packages/jinja2/environment.py", line 780, in handle_exception
    reraise(exc_type, exc_value, tb)
  File "/Users/amyliz/Documents/Computer Science/Python/microblog/venv/lib/python3.7/site-packages/jinja2/_compat.py", line 37, in reraise
    raise value.with_traceback(tb)
  File "/Users/amyliz/Documents/Computer Science/Python/microblog/app/templates/base.html", line 82, in template
    {% block content %}{% endblock %}
  File "/Users/amyliz/Documents/Computer Science/Python/microblog/venv/lib/python3.7/site-packages/jinja2/environment.py", line 1005, in render
    return concat(self.root_render_func(self.new_context(vars)))
  File "/Users/amyliz/Documents/Computer Science/Python/microblog/app/templates/404.html", line 1, in top-level template code
    {% extends "base.html" %}
  File "/Users/amyliz/Documents/Computer Science/Python/microblog/venv/lib/python3.7/site-packages/jinja2/environment.py", line 780, in handle_exception
    reraise(exc_type, exc_value, tb)
  File "/Users/amyliz/Documents/Computer Science/Python/microblog/venv/lib/python3.7/site-packages/jinja2/_compat.py", line 37, in reraise
    raise value.with_traceback(tb)
  File "/Users/amyliz/Documents/Computer Science/Python/microblog/app/templates/base.html", line 82, in template
    {% block content %}{% endblock %}
  File "/Users/amyliz/Documents/Computer Science/Python/microblog/venv/lib/python3.7/site-packages/jinja2/environment.py", line 543, in _generate
    optimized=self.optimized)
  File "/Users/amyliz/Documents/Computer Science/Python/microblog/venv/lib/python3.7/site-packages/jinja2/compiler.py", line 82, in generate
    generator.visit(node)
  File "/Users/amyliz/Documents/Computer Science/Python/microblog/venv/lib/python3.7/site-packages/jinja2/visitor.py", line 38, in visit
    return f(node, *args, **kwargs)
  File "/Users/amyliz/Documents/Computer Science/Python/microblog/venv/lib/python3.7/site-packages/jinja2/compiler.py", line 718, in visit_Template
    self.fail('block %r defined twice' % block.name, block.lineno)
  File "/Users/amyliz/Documents/Computer Science/Python/microblog/venv/lib/python3.7/site-packages/jinja2/compiler.py", line 315, in fail
    raise TemplateAssertionError(msg, lineno, self.name, self.filename)
jinja2.exceptions.TemplateAssertionError: block 'content' defined twice
2019-09-03 11:25:16,349 INFO: Microblog startup [in /Users/amyliz/Documents/Computer Science/Python/microblog/app/__init__.py:38]
